Traceback (most recent call last):
  File "datacollector.py", line 33, in <module>
    executeSomething()
  File "datacollector.py", line 7, in executeSomething
    newpid = os.fork()
OSError: [Errno 11] Resource temporarily unavailable
Traceback (most recent call last):
  File "datacollector.py", line 33, in <module>
    executeSomething()
  File "datacollector.py", line 26, in executeSomething
    mycursor.execute(sql, val)
  File "/usr/local/lib/python2.7/dist-packages/mysql/connector/cursor.py", line 559, in execute
    self._handle_result(self._connection.cmd_query(stmt))
  File "/usr/local/lib/python2.7/dist-packages/mysql/connector/connection.py", line 494, in cmd_query
    result = self._handle_result(self._send_cmd(ServerCmd.QUERY, query))
  File "/usr/local/lib/python2.7/dist-packages/mysql/connector/connection.py", line 396, in _handle_result
    raise errors.get_exception(packet)
mysql.connector.errors.IntegrityError: 1062 (23000): Duplicate entry '2-1542015568' for key 'PRIMARY'
Traceback (most recent call last):
  File "datacollector.py", line 33, in <module>
    executeSomething()
  File "datacollector.py", line 17, in executeSomething
    dom = minidom.parse(urllib2.urlopen(url)) # parse the data
  File "/usr/lib/python2.7/urllib2.py", line 154, in urlopen
    return opener.open(url, data, timeout)
  File "/usr/lib/python2.7/urllib2.py", line 429, in open
    response = self._open(req, data)
  File "/usr/lib/python2.7/urllib2.py", line 447, in _open
    '_open', req)
  File "/usr/lib/python2.7/urllib2.py", line 407, in _call_chain
    result = func(*args)
  File "/usr/lib/python2.7/urllib2.py", line 1228, in http_open
    return self.do_open(httplib.HTTPConnection, req)
  File "/usr/lib/python2.7/urllib2.py", line 1201, in do_open
    r = h.getresponse(buffering=True)
  File "/usr/lib/python2.7/httplib.py", line 1121, in getresponse
    response.begin()
  File "/usr/lib/python2.7/httplib.py", line 438, in begin
    version, status, reason = self._read_status()
  File "/usr/lib/python2.7/httplib.py", line 394, in _read_status
    line = self.fp.readline(_MAXLINE + 1)
  File "/usr/lib/python2.7/socket.py", line 480, in readline
    data = self._sock.recv(self._rbufsize)
socket.error: [Errno 104] Connection reset by peer
